<?xml version="1.0" ?>
<robot name="puma_robot" xmlns:xacro="http://www.ros.org/wiki/xacro">

    <!-- ============================================== -->
    <!-- Material Definitions                          -->
    <!-- ============================================== -->
    <material name="blue">
        <color rgba="0.0 0.0 0.8 1.0"/>
    </material>
    <material name="cyan">
        <color rgba="0.0 0.8 0.8 1.0"/>
    </material>
    <material name="green">
        <color rgba="0.0 0.8 0.0 1.0"/>
    </material>
    <material name="red">
        <color rgba="0.8 0.0 0.0 1.0"/>
    </material>
    <material name="orange">
        <color rgba="1.0 0.5 0.0 1.0"/>
    </material>
    <material name="grey">
        <color rgba="0.5 0.5 0.5 1.0"/>
    </material>

    <!-- ============================================== -->
    <!-- Dummy root for KDL                            -->
    <!-- ============================================== -->
    <link name="dummy_root"/>

    <joint name="basejoint" type="fixed">
        <parent link="dummy_root"/>
        <child link="base_link"/>
        <origin xyz="0 0 0" rpy="0 0 0"/>
    </joint>

    <!-- ============================================== -->
    <!-- Link: base_link (基座)                         -->
    <!-- Cylinder: radius=0.35, length=0.1             -->
    <!-- Origin: 0 0 0.05                              -->
    <!-- ============================================== -->
    <link name="base_link">
        <visual>
            <origin xyz="0 0 0.05" rpy="0 0 0"/>
            <geometry>
                <cylinder radius="0.35" length="0.1"/>
            </geometry>
            <material name="grey"/>
        </visual>
        <collision>
            <origin xyz="0 0 0.05" rpy="0 0 0"/>
            <geometry>
                <cylinder radius="0.35" length="0.1"/>
            </geometry>
        </collision>
        <inertial>
            <mass value="10.0"/>
            <origin xyz="0 0 0.05" rpy="0 0 0"/>
            <inertia ixx="1.0" ixy="0.0" ixz="0.0" iyy="1.0" iyz="0.0" izz="1.0"/>
        </inertial>
    </link>

    <!-- ============================================== -->
    <!-- Joint: J_0 (Revolute)                         -->
    <!-- Origin: xyz="0 0 0.1", Axis: Z                -->
    <!-- ============================================== -->
    <joint name="J_0" type="revolute">
        <parent link="base_link"/>
        <child link="link_01"/>
        <origin xyz="0 0 0.1" rpy="0 0 0"/>
        <axis xyz="0 0 1"/>
        <limit lower="-3.14" upper="3.14" effort="100" velocity="1.0"/>
    </joint>

    <!-- ============================================== -->
    <!-- Link: link_01 (立柱)                           -->
    <!-- Cylinder: radius=0.15, length=1.1             -->
    <!-- ============================================== -->
    <link name="link_01">
        <visual>
            <origin xyz="0 0 0.55" rpy="0 0 0"/>
            <geometry>
                <cylinder radius="0.15" length="1.1"/>
            </geometry>
            <material name="blue"/>
        </visual>
        <collision>
            <origin xyz="0 0 0.55" rpy="0 0 0"/>
            <geometry>
                <cylinder radius="0.15" length="1.1"/>
            </geometry>
        </collision>
        <inertial>
            <mass value="5.0"/>
            <origin xyz="0 0 0.55" rpy="0 0 0"/>
            <inertia ixx="0.5" ixy="0.0" ixz="0.0" iyy="0.5" iyz="0.0" izz="0.5"/>
        </inertial>
    </link>

    <!-- ============================================== -->
    <!-- Joint: J_F0 (Fixed) - 坐标系转换               -->
    <!-- Origin: xyz="0 0 1.3", rpy="-pi/2 -pi/2 0"    -->
    <!-- ============================================== -->
    <joint name="J_F0" type="fixed">
        <parent link="link_01"/>
        <child link="link_02"/>
        <origin xyz="0 0 1.3" rpy="-1.5708 -1.5708 0"/>
    </joint>

    <!-- ============================================== -->
    <!-- Link: link_02 (水平连接圆柱)                   -->
    <!-- Cylinder: radius=0.2, length=0.5              -->
    <!-- ============================================== -->
    <link name="link_02">
        <visual>
            <origin xyz="0 0 0" rpy="0 0 0"/>
            <geometry>
                <cylinder radius="0.2" length="0.5"/>
            </geometry>
            <material name="cyan"/>
        </visual>
        <collision>
            <origin xyz="0 0 0" rpy="0 0 0"/>
            <geometry>
                <cylinder radius="0.2" length="0.5"/>
            </geometry>
        </collision>
        <inertial>
            <mass value="2.0"/>
            <origin xyz="0 0 0" rpy="0 0 0"/>
            <inertia ixx="0.2" ixy="0.0" ixz="0.0" iyy="0.2" iyz="0.0" izz="0.2"/>
        </inertial>
    </link>

    <!-- ============================================== -->
    <!-- Joint: J_1 (Revolute)                         -->
    <!-- Origin: xyz="0 0 0.35", Axis: Z               -->
    <!-- ============================================== -->
    <joint name="J_1" type="revolute">
        <parent link="link_02"/>
        <child link="link_03"/>
        <origin xyz="0 0 0.35" rpy="0 0 0"/>
        <axis xyz="0 0 1"/>
        <limit lower="-3.14" upper="3.14" effort="100" velocity="1.0"/>
    </joint>

    <!-- ============================================== -->
    <!-- Link: link_03 (大臂)                           -->
    <!-- Box: size="0.3 1.2 0.2"                       -->
    <!-- ============================================== -->
    <link name="link_03">
        <visual>
            <origin xyz="0 0.4 0" rpy="0 0 0"/>
            <geometry>
                <box size="0.3 1.2 0.2"/>
            </geometry>
            <material name="green"/>
        </visual>
        <collision>
            <origin xyz="0 0.6 0" rpy="0 0 0"/>
            <geometry>
                <box size="0.3 1.2 0.2"/>
            </geometry>
        </collision>
        <inertial>
            <mass value="3.0"/>
            <origin xyz="0 0.6 0" rpy="0 0 0"/>
            <inertia ixx="0.3" ixy="0.0" ixz="0.0" iyy="0.3" iyz="0.0" izz="0.3"/>
        </inertial>
    </link>

    <!-- ============================================== -->
    <!-- Joint: J_2 (Revolute)                         -->
    <!-- Origin: xyz="0 1.0 0.2", Axis: Z              -->
    <!-- ============================================== -->
    <joint name="J_2" type="revolute">
        <parent link="link_03"/>
        <child link="link_04"/>
        <origin xyz="0 0.85 0.15" rpy="0 0 0"/>
        <axis xyz="0 0 1"/>
        <limit lower="-3.14" upper="3.14" effort="100" velocity="1.0"/>
    </joint>

    <!-- ============================================== -->
    <!-- Link: link_04 (小臂)                           -->
    <!-- Box: size="0.2 1.0 0.1"                       -->
    <!-- ============================================== -->
    <link name="link_04">
        <visual>
            <origin xyz="0 0.4 0" rpy="0 0 0"/>
            <geometry>
                <box size="0.2 1.0 0.1"/>
            </geometry>
            <material name="orange"/>
        </visual>
        <collision>
            <origin xyz="0 0.5 -0.05" rpy="0 0 0"/>
            <geometry>
                <box size="0.2 1.0 0.1"/>
            </geometry>
        </collision>
        <inertial>
            <mass value="2.0"/>
            <origin xyz="0 0.5 -0.05" rpy="0 0 0"/>
            <inertia ixx="0.2" ixy="0.0" ixz="0.0" iyy="0.2" iyz="0.0" izz="0.2"/>
        </inertial>
    </link>

    <!-- ============================================== -->
    <!-- Joint: J_3 (Revolute)                         -->
    <!-- Origin: xyz="0 0.9 -0.05", rpy="pi/2 pi/2 pi" -->
    <!-- ============================================== -->
    <joint name="J_3" type="revolute">
        <parent link="link_04"/>
        <child link="effector"/>
        <origin xyz="0 1.0 0" rpy="1.5708 1.5708 3.14159"/>
        <axis xyz="0 0 1"/>
        <limit lower="-3.14" upper="3.14" effort="100" velocity="1.0"/>
    </joint>

    <!-- ============================================== -->
    <!-- Link: effector (末端执行器)                    -->
    <!-- Box: size="0.2 0.2 0.1"                       -->
    <!-- ============================================== -->
    <link name="effector">
        <visual>
            <origin xyz="-0.0 0 -0.05" rpy="0 0 0"/>
            <geometry>
                <box size="0.2 0.2 0.1"/>
            </geometry>
            <material name="red"/>
        </visual>
        <collision>
            <origin xyz="0 0 0" rpy="0 0 0"/>
            <geometry>
                <box size="0.2 0.2 0.1"/>
            </geometry>
        </collision>
        <inertial>
            <mass value="0.5"/>
            <origin xyz="0 0 0" rpy="0 0 0"/>
            <inertia ixx="0.01" ixy="0.0" ixz="0.0" iyy="0.01" iyz="0.0" izz="0.01"/>
        </inertial>
    </link>

</robot>
